<?xml version="1.0" ?>
<sdf version="1.7">
	<model name="Cabinet_1">

		<link name="base">
			<visual name="cabinet_1_visual">
				<pose>0 0 0 0 0 0</pose>
				<geometry>
					<mesh>
						<scale>1 1 1</scale>
						<uri>meshes/Cabinet_1/CabinetOuter.fbx</uri>
					</mesh>
				</geometry>
			</visual>
		</link>

		<joint name="big_drawer_joint" type="prismatic">
			<pose>0 0 0.02 0 1.570796 0</pose>
			<axis>
				<xyz>0 0 1</xyz>
			</axis>
			<parent>base</parent>
			<child>big_drawer</child>
			<limit>
				<lower>0</lower>
				<upper>0.5</upper>
				<velocity>0</velocity>
				<effort>0</effort>
			</limit>
		</joint>
		<link name="big_drawer">
			<visual name="big_drawer_visual">
				<pose>-0.18 0 0.315 0 -1.570796 0</pose>
				<geometry>
					<mesh>
						<scale>1 1 1</scale>
						<uri>meshes/Cabinet_1/BigDrawer.fbx</uri>
					</mesh>
				</geometry>
			</visual>
		</link>
		
		<joint name="big_drawer_handle_joint" type="fixed">
			<pose>-0.18 0 0.315 0 0 0</pose>
			<parent>big_drawer</parent>
			<child>big_drawer_handle</child>
		</joint>
		<link name="big_drawer_handle">
			<visual name="big_drawer_handle_visual">
				<pose>0 0 0.05 0 -1.570796 0</pose>
				<geometry>
					<mesh>
						<scale>1 1 1</scale>
						<uri>meshes/Cabinet_1/DrawerHandle.fbx</uri>
					</mesh>
				</geometry>
			</visual>
		</link>
		<joint name="small_drawer_1_joint" type="prismatic">
			<pose>0 0 0.4 0 1.570796 0</pose>
			<axis>
				<xyz>0 0 1</xyz>
			</axis>
			<parent>base</parent>
			<child>small_drawer_1</child>
			<limit>
				<lower>0</lower>
				<upper>0.5</upper>
				<velocity>0</velocity>
				<effort>0</effort>
			</limit>
		</joint>
		<link name="small_drawer_1">
			<visual name="samll_drawer_1_visual">
				<pose>-0.1 0 0.315 0 -1.570796 0</pose>
				<geometry>
					<mesh>
						<scale>1 1 1</scale>
						<uri>meshes/Cabinet_1/SmallDrawer.fbx</uri>
					</mesh>
				</geometry>
			</visual>
		</link>
		
		<joint name="small_drawer_1_handle_joint" type="fixed">
			<pose>-0.1 0 0.315 0 0 0</pose>
			<parent>small_drawer_1</parent>
			<child>small_drawer_1_handle</child>
		</joint>
		<link name="small_drawer_1_handle">
			<visual name="small_drawer_1_handle_visual">
				<pose>0 0 0.05 0 -1.570796 0</pose>
				<geometry>
					<mesh>
						<scale>1 1 1</scale>
						<uri>meshes/Cabinet_1/DrawerHandle.fbx</uri>
					</mesh>
				</geometry>
			</visual>
		</link>

	<joint name="small_drawer_2_joint" type="prismatic">
			<pose>0 0 0.6 0 1.570796 0</pose>
			<axis>
				<xyz>0 0 1</xyz>
			</axis>
			<parent>base</parent>
			<child>small_drawer_2</child>
			<limit>
				<lower>0</lower>
				<upper>0.5</upper>
				<velocity>0</velocity>
				<effort>0</effort>
			</limit>
		</joint>
		<link name="small_drawer_2">
			<visual name="samll_drawer_2_visual">
				<pose>-0.1 0 0.315 0 -1.570796 0</pose>
				<geometry>
					<mesh>
						<scale>1 1 1</scale>
						<uri>meshes/Cabinet_1/SmallDrawer.fbx</uri>
					</mesh>
				</geometry>
			</visual>
		</link>
		
		<joint name="small_drawer_2_handle_joint" type="fixed">
			<pose>-0.1 0 0.315 0 0 0</pose>
			<parent>small_drawer_2</parent>
			<child>small_drawer_2_handle</child>
		</joint>
		<link name="small_drawer_2_handle">
			<visual name="small_drawer_2_handle_visual">
				<pose>0 0 0.05 0 -1.570796 0</pose>
				<geometry>
					<mesh>
						<scale>1 1 1</scale>
						<uri>meshes/Cabinet_1/DrawerHandle.fbx</uri>
					</mesh>
				</geometry>
			</visual>
		</link>
		
	</model>
</sdf>
