<sdf version='1.7'>
  <model name='baxter'>
    <link name='base'>
      <inertial>
        <pose>0 -0 3e-06 0 -0 0</pose>
        <mass>96.2011</mass>
        <inertia>
          <ixx>6.91297</ixx>
          <ixy>0.00068017</ixy>
          <ixz>0.64779</ixz>
          <iyy>7.74978</iyy>
          <iyz>0.00434511</iyz>
          <izz>5.76418</izz>
        </inertia>
      </inertial>
      <collision name='base_fixed_joint_lump__collision_head_link_1_collision'>
        <pose>0.04 -0.04 0.75 0 -0 0</pose>
        <geometry>
          <sphere>
            <radius>0.22</radius>
          </sphere>
        </geometry>
      </collision>
      <collision name='base_fixed_joint_lump__collision_head_link_2_collision_1'>
        <pose>0.04 0.04 0.75 0 -0 0</pose>
        <geometry>
          <sphere>
            <radius>0.22</radius>
          </sphere>
        </geometry>
      </collision>
      <collision name='base_fixed_joint_lump__torso_collision_2'>
        <pose>0 0 0 0 -0 0</pose>
        <geometry>
          <mesh>
            <scale>1 1 1</scale>
            <uri>model://baxter_description/meshes/torso/base_link_collision.DAE</uri>
          </mesh>
        </geometry>
        <surface>
          <contact>
            <ode/>
          </contact>
          <friction>
            <ode/>
          </friction>
        </surface>
      </collision>
      <collision name='base_fixed_joint_lump__pedestal_collision_3'>
        <pose>0 0 0 0 -0 0</pose>
        <geometry>
          <mesh>
            <scale>1 1 1</scale>
            <uri>model://baxter_description/meshes/base/pedestal_link_collision.DAE</uri>
          </mesh>
        </geometry>
      </collision>
      <collision name='base_fixed_joint_lump__sonar_ring_collision_4'>
        <pose>0.0947 0 0.817 0 -0 0</pose>
        <geometry>
          <sphere>
            <radius>0.001</radius>
          </sphere>
        </geometry>
        <surface>
          <contact>
            <ode/>
          </contact>
          <friction>
            <ode/>
          </friction>
        </surface>
      </collision>
      <visual name='base_fixed_joint_lump__collision_head_link_1_visual'>
        <pose>0.11 0 0.75 0 -0 0</pose>
        <geometry>
          <sphere>
            <radius>0.001</radius>
          </sphere>
        </geometry>
      </visual>
      <visual name='base_fixed_joint_lump__collision_head_link_2_visual_1'>
        <pose>0.11 0 0.75 0 -0 0</pose>
        <geometry>
          <sphere>
            <radius>0.001</radius>
          </sphere>
        </geometry>
      </visual>
      <visual name='base_fixed_joint_lump__torso_visual_2'>
        <pose>0 0 0 0 -0 0</pose>
        <geometry>
          <mesh>
            <scale>1 1 1</scale>
            <uri>model://baxter_description/meshes/torso/base_link.DAE</uri>
          </mesh>
        </geometry>
      </visual>
      <visual name='base_fixed_joint_lump__pedestal_visual_3'>
        <pose>0 0 0 0 -0 0</pose>
        <geometry>
          <mesh>
            <scale>1 1 1</scale>
            <uri>model://baxter_description/meshes/base/PEDESTAL.DAE</uri>
          </mesh>
        </geometry>
      </visual>
      <visual name='base_fixed_joint_lump__sonar_ring_visual_4'>
        <pose>0.06 0 0.82653 0 -0 0</pose>
        <geometry>
          <cylinder>
            <length>0.01</length>
            <radius>0.085</radius>
          </cylinder>
        </geometry>
      </visual>
      <self_collide>1</self_collide>
      <sensor name='sonar' type='ray'>
        <ray>
          <scan>
            <horizontal>
              <samples>12</samples>
              <resolution>1</resolution>
              <min_angle>-3.14</min_angle>
              <max_angle>3.14</max_angle>
            </horizontal>
            <vertical>
              <samples>2</samples>
              <resolution>1</resolution>
              <min_angle>-0.001</min_angle>
              <max_angle>0</max_angle>
            </vertical>
          </scan>
          <range>
            <min>0.05</min>
            <max>50</max>
          </range>
        </ray>
        <plugin name='sonar_plugin' filename='libgazebo_ros_block_laser.so'>
          <gaussianNoise>0.00</gaussianNoise>
          <alwaysOn>1</alwaysOn>
          <updateRate>100.0</updateRate>
          <topicName>/robot/sonar/head_sonar/state</topicName>
          <frameName>sonar_ring</frameName>
        </plugin>
        <always_on>1</always_on>
        <update_rate>100</update_rate>
        <pose>0.0947 0 0.817 0 -0 0</pose>
      </sensor>
    </link>
    <joint name='head_pan' type='revolute'>
      <pose relative_to='base'>0.06 0 0.686 0 -0 0</pose>
      <parent>base</parent>
      <child>head</child>
      <axis>
        <xyz>0 0 1</xyz>
        <limit>
          <lower>-1.5708</lower>
          <upper>1.5708</upper>
          <effort>50000</effort>
          <velocity>10000</velocity>
        </limit>
        <dynamics>
          <damping>0.7</damping>
          <friction>0</friction>
          <spring_reference>0</spring_reference>
          <spring_stiffness>0</spring_stiffness>
        </dynamics>
      </axis>
      <physics>
        <ode>
          <implicit_spring_damper>1</implicit_spring_damper>
          <cfm_damping>1</cfm_damping>
          <limit>
            <cfm>0</cfm>
            <erp>0.2</erp>
          </limit>
        </ode>
      </physics>
    </joint>
    <link name='head'>
      <pose relative_to='head_pan'>0 0 0 0 -0 0</pose>
      <inertial>
        <pose>0.054677 0 5e-06 0 -0 0</pose>
        <mass>0.988238</mass>
        <inertia>
          <ixx>0.00620194</ixx>
          <ixy>0.000202093</ixy>
          <ixz>0.000495898</ixz>
          <iyy>0.010977</iyy>
          <iyz>-0.00109806</iyz>
          <izz>0.00983914</izz>
        </inertia>
      </inertial>
      <collision name='head_collision'>
        <pose>0 0 0 0 -0 0</pose>
        <geometry>
          <sphere>
            <radius>0.001</radius>
          </sphere>
        </geometry>
      </collision>
      <collision name='head_fixed_joint_lump__screen_collision_1'>
        <pose>0.1227 0 0 1.75057 -0 1.5708</pose>
        <geometry>
          <sphere>
            <radius>0.001</radius>
          </sphere>
        </geometry>
      </collision>
      <visual name='head_visual'>
        <pose>0 0 0.00953 0 -0 0</pose>
        <geometry>
          <mesh>
            <scale>1 1 1</scale>
            <uri>model://baxter_description/meshes/head/H0.DAE</uri>
          </mesh>
        </geometry>
      </visual>
      <visual name='head_fixed_joint_lump__screen_visual_1'>
        <pose>0.086855 0 -0.003172 1.5708 0.179774 0</pose>
        <geometry>
          <mesh>
            <scale>1 1 1</scale>
            <uri>model://baxter_description/meshes/head/H1.DAE</uri>
          </mesh>
        </geometry>
      </visual>
      <visual name='head_fixed_joint_lump__display_visual_2'>
        <pose>0.119839 0 -0.015742 2.01237 -0 1.5708</pose>
        <geometry>
          <box>
            <size>0.218 0.16 0.001</size>
          </box>
        </geometry>
        <plugin name='screen_video_controller' filename='libgazebo_ros_video.so'>
          <height>600</height>
          <width>1024</width>
          <topicName>/robot/xdisplay</topicName>
        </plugin>
      </visual>
      <sensor name='head_camera' type='camera'>
        <update_rate>30</update_rate>
        <camera name='head_camera'>
          <pose>0 0.21 0 0 -0.8 -1.5708</pose>
          <horizontal_fov>1.39626</horizontal_fov>
          <image>
            <width>800</width>
            <height>800</height>
            <format>R8G8B8</format>
          </image>
          <clip>
            <near>0.02</near>
            <far>300</far>
          </clip>
          <noise>
            <type>gaussian</type>
            <mean>0</mean>
            <stddev>0.007</stddev>
          </noise>
        </camera>
        <plugin name='camera_controller' filename='libgazebo_ros_camera.so'>
          <alwaysOn>1</alwaysOn>
          <updateRate>0.0</updateRate>
          <cameraName>head_camera</cameraName>
          <imageTopicName>image</imageTopicName>
          <cameraInfoTopicName>camera_info</cameraInfoTopicName>
          <frameName>head_camera</frameName>
          <hackBaseline>0.07</hackBaseline>
          <distortionK1>0.0</distortionK1>
          <distortionK2>0.0</distortionK2>
          <distortionK3>0.0</distortionK3>
          <distortionT1>0.0</distortionT1>
          <distortionT2>0.0</distortionT2>
          <robotNamespace>/cameras</robotNamespace>
        </plugin>
        <pose>0.12839 0 0.06368 1.75057 -0 1.5708</pose>
      </sensor>
    </link>
    <joint name='left_s0' type='revolute'>
      <pose relative_to='base'>0.064027 0.259027 0.129626 0 -0 0.7854</pose>
      <parent>base</parent>
      <child>left_upper_shoulder</child>
      <axis>
        <xyz>0 0 1</xyz>
        <limit>
          <lower>-1.70168</lower>
          <upper>1.70168</upper>
          <effort>50</effort>
          <velocity>1.5</velocity>
        </limit>
        <dynamics>
          <damping>0.7</damping>
          <friction>0</friction>
          <spring_reference>0</spring_reference>
          <spring_stiffness>0</spring_stiffness>
        </dynamics>
      </axis>
      <physics>
        <ode>
          <implicit_spring_damper>1</implicit_spring_damper>
          <cfm_damping>1</cfm_damping>
          <limit>
            <cfm>0</cfm>
            <erp>0.2</erp>
          </limit>
        </ode>
      </physics>
    </joint>
    <link name='left_upper_shoulder'>
      <pose relative_to='left_s0'>0 0 0 0 -0 0</pose>
      <inertial>
        <pose>0.01783 0.00086 0.19127 0 -0 0</pose>
        <mass>5.70044</mass>
        <inertia>
          <ixx>0.047091</ixx>
          <ixy>0.000127876</ixy>
          <ixz>0.0061487</ixz>
          <iyy>0.0376698</iyy>
          <iyz>0.000780869</iyz>
          <izz>0.0359599</izz>
        </inertia>
      </inertial>
      <collision name='left_upper_shoulder_collision'>
        <pose>0 0 0.1361 0 -0 0</pose>
        <geometry>
          <cylinder>
            <length>0.2722</length>
            <radius>0.06</radius>
          </cylinder>
        </geometry>
      </collision>
      <visual name='left_upper_shoulder_visual'>
        <pose>0 0 0 0 -0 0</pose>
        <geometry>
          <mesh>
            <scale>1 1 1</scale>
            <uri>model://baxter_description/meshes/upper_shoulder/S0.DAE</uri>
          </mesh>
        </geometry>
      </visual>
    </link>
    <joint name='left_s1' type='revolute'>
      <pose relative_to='left_upper_shoulder'>0.069 0 0.27035 -1.5708 0 0</pose>
      <parent>left_upper_shoulder</parent>
      <child>left_lower_shoulder</child>
      <axis>
        <xyz>0 0 1</xyz>
        <limit>
          <lower>-2.147</lower>
          <upper>1.047</upper>
          <effort>100</effort>
          <velocity>1.5</velocity>
        </limit>
        <dynamics>
          <damping>0.7</damping>
          <friction>0</friction>
          <spring_reference>0</spring_reference>
          <spring_stiffness>0</spring_stiffness>
        </dynamics>
      </axis>
      <physics>
        <ode>
          <implicit_spring_damper>1</implicit_spring_damper>
          <cfm_damping>1</cfm_damping>
          <limit>
            <cfm>0</cfm>
            <erp>0.2</erp>
          </limit>
        </ode>
      </physics>
    </joint>
    <link name='left_lower_shoulder'>
      <pose relative_to='left_s1'>0 0 0 0 -0 0</pose>
      <inertial>
        <pose>0.068451 0.00269 -0.00529 0 -0 0</pose>
        <mass>3.22708</mass>
        <inertia>
          <ixx>0.0117521</ixx>
          <ixy>-0.000300954</ixy>
          <ixz>0.00207674</ixz>
          <iyy>0.0278861</iyy>
          <iyz>-0.000188219</iyz>
          <izz>0.0207877</izz>
        </inertia>
      </inertial>
      <collision name='left_lower_shoulder_collision'>
        <pose>0 0 0 0 -0 0</pose>
        <geometry>
          <cylinder>
            <length>0.12</length>
            <radius>0.06</radius>
          </cylinder>
        </geometry>
      </collision>
      <collision name='left_lower_shoulder_fixed_joint_lump__left_upper_elbow_visual_collision_1'>
        <pose>0.2435 -0 0 1.5708 -0 1.5708</pose>
        <geometry>
          <cylinder>
            <length>0.273</length>
            <radius>0.06</radius>
          </cylinder>
        </geometry>
      </collision>
      <visual name='left_lower_shoulder_visual'>
        <pose>0 0 0 0 -0 0</pose>
        <geometry>
          <mesh>
            <scale>1 1 1</scale>
            <uri>model://baxter_description/meshes/lower_shoulder/S1.DAE</uri>
          </mesh>
        </geometry>
      </visual>
    </link>
    <joint name='left_e0' type='revolute'>
      <pose relative_to='left_lower_shoulder'>0.102 0 0 1.5708 -0 1.5708</pose>
      <parent>left_lower_shoulder</parent>
      <child>left_upper_elbow</child>
      <axis>
        <xyz>0 0 1</xyz>
        <limit>
          <lower>-3.05418</lower>
          <upper>3.05418</upper>
          <effort>50</effort>
          <velocity>1.5</velocity>
        </limit>
        <dynamics>
          <damping>0.7</damping>
          <friction>0</friction>
          <spring_reference>0</spring_reference>
          <spring_stiffness>0</spring_stiffness>
        </dynamics>
      </axis>
      <physics>
        <ode>
          <implicit_spring_damper>1</implicit_spring_damper>
          <cfm_damping>1</cfm_damping>
          <limit>
            <cfm>0</cfm>
            <erp>0.2</erp>
          </limit>
        </ode>
      </physics>
    </joint>
    <link name='left_upper_elbow'>
      <pose relative_to='left_e0'>0 0 0 0 -0 0</pose>
      <inertial>
        <pose>-0.00276 0.00132 0.18086 0 -0 0</pose>
        <mass>4.31272</mass>
        <inertia>
          <ixx>0.0266173</ixx>
          <ixy>0.000292706</ixy>
          <ixz>0.0039219</ixz>
          <iyy>0.0284436</iyy>
          <iyz>0.00108389</iyz>
          <izz>0.0124801</izz>
        </inertia>
      </inertial>
      <collision name='left_upper_elbow_collision'>
        <pose>0 0 -0.0535 0 -0 0</pose>
        <geometry>
          <cylinder>
            <length>0.107</length>
            <radius>0.06</radius>
          </cylinder>
        </geometry>
      </collision>
      <visual name='left_upper_elbow_visual'>
        <pose>0 0 0 0 -0 0</pose>
        <geometry>
          <mesh>
            <scale>1 1 1</scale>
            <uri>model://baxter_description/meshes/upper_elbow/E0.DAE</uri>
          </mesh>
        </geometry>
      </visual>
    </link>
    <joint name='left_e1' type='revolute'>
      <pose relative_to='left_upper_elbow'>0.069 0 0.26242 -1.5708 -1.5708 0</pose>
      <parent>left_upper_elbow</parent>
      <child>left_lower_elbow</child>
      <axis>
        <xyz>0 0 1</xyz>
        <limit>
          <lower>-0.05</lower>
          <upper>2.618</upper>
          <effort>50</effort>
          <velocity>1.5</velocity>
        </limit>
        <dynamics>
          <damping>0.7</damping>
          <friction>0</friction>
          <spring_reference>0</spring_reference>
          <spring_stiffness>0</spring_stiffness>
        </dynamics>
      </axis>
      <physics>
        <ode>
          <implicit_spring_damper>1</implicit_spring_damper>
          <cfm_damping>1</cfm_damping>
          <limit>
            <cfm>0</cfm>
            <erp>0.2</erp>
          </limit>
        </ode>
      </physics>
    </joint>
    <link name='left_lower_elbow'>
      <pose relative_to='left_e1'>0 0 0 0 -0 0</pose>
      <inertial>
        <pose>0.026113 0.00159 -0.011169 0 -0 0</pose>
        <mass>2.07216</mass>
        <inertia>
          <ixx>0.00711585</ixx>
          <ixy>0.000360372</ixy>
          <ixz>0.00074588</ixz>
          <iyy>0.0131827</iyy>
          <iyz>-0.000196632</iyz>
          <izz>0.00926891</izz>
        </inertia>
      </inertial>
      <collision name='left_lower_elbow_collision'>
        <pose>0 0 0 0 -0 0</pose>
        <geometry>
          <cylinder>
            <length>0.1</length>
            <radius>0.06</radius>
          </cylinder>
        </geometry>
      </collision>
      <collision name='left_lower_elbow_fixed_joint_lump__left_upper_forearm_visual_collision_1'>
        <pose>0.224 -0 0 1.5708 -0 1.5708</pose>
        <geometry>
          <cylinder>
            <length>0.272</length>
            <radius>0.06</radius>
          </cylinder>
        </geometry>
      </collision>
      <visual name='left_lower_elbow_visual'>
        <pose>0 0 0 0 -0 0</pose>
        <geometry>
          <mesh>
            <scale>1 1 1</scale>
            <uri>model://baxter_description/meshes/lower_elbow/E1.DAE</uri>
          </mesh>
        </geometry>
      </visual>
    </link>
    <joint name='left_w0' type='revolute'>
      <pose relative_to='left_lower_elbow'>0.10359 0 0 1.5708 -0 1.5708</pose>
      <parent>left_lower_elbow</parent>
      <child>left_upper_forearm</child>
      <axis>
        <xyz>0 0 1</xyz>
        <limit>
          <lower>-3.059</lower>
          <upper>3.059</upper>
          <effort>15</effort>
          <velocity>4</velocity>
        </limit>
        <dynamics>
          <damping>0.7</damping>
          <friction>0</friction>
          <spring_reference>0</spring_reference>
          <spring_stiffness>0</spring_stiffness>
        </dynamics>
      </axis>
      <physics>
        <ode>
          <implicit_spring_damper>1</implicit_spring_damper>
          <cfm_damping>1</cfm_damping>
          <limit>
            <cfm>0</cfm>
            <erp>0.2</erp>
          </limit>
        </ode>
      </physics>
    </joint>
    <link name='left_upper_forearm'>
      <pose relative_to='left_w0'>0 0 0 0 -0 0</pose>
      <inertial>
        <pose>-0.001682 0.0046 0.139519 0 -0 0</pose>
        <mass>2.24675</mass>
        <inertia>
          <ixx>0.0166775</ixx>
          <ixy>0.000184012</ixy>
          <ixz>0.000186469</ixz>
          <iyy>0.0167549</iyy>
          <iyz>-0.000647332</iyz>
          <izz>0.00374662</izz>
        </inertia>
      </inertial>
      <collision name='left_upper_forearm_collision'>
        <pose>0 0 -0.044 0 -0 0</pose>
        <geometry>
          <cylinder>
            <length>0.088</length>
            <radius>0.06</radius>
          </cylinder>
        </geometry>
      </collision>
      <visual name='left_upper_forearm_visual'>
        <pose>0 0 0 0 -0 0</pose>
        <geometry>
          <mesh>
            <scale>1 1 1</scale>
            <uri>model://baxter_description/meshes/upper_forearm/W0.DAE</uri>
          </mesh>
        </geometry>
      </visual>
    </link>
    <joint name='left_w1' type='revolute'>
      <pose relative_to='left_upper_forearm'>0.01 0 0.2707 -1.5708 -1.5708 0</pose>
      <parent>left_upper_forearm</parent>
      <child>left_lower_forearm</child>
      <axis>
        <xyz>0 0 1</xyz>
        <limit>
          <lower>-1.5708</lower>
          <upper>2.094</upper>
          <effort>15</effort>
          <velocity>4</velocity>
        </limit>
        <dynamics>
          <damping>0.7</damping>
          <friction>0</friction>
          <spring_reference>0</spring_reference>
          <spring_stiffness>0</spring_stiffness>
        </dynamics>
      </axis>
      <physics>
        <ode>
          <implicit_spring_damper>1</implicit_spring_damper>
          <cfm_damping>1</cfm_damping>
          <limit>
            <cfm>0</cfm>
            <erp>0.2</erp>
          </limit>
        </ode>
      </physics>
    </joint>
    <link name='left_lower_forearm'>
      <pose relative_to='left_w1'>0 0 0 0 -0 0</pose>
      <inertial>
        <pose>0.06041 0.00697 0.006 0 -0 0</pose>
        <mass>1.60979</mass>
        <inertia>
          <ixx>0.00387607</ixx>
          <ixy>-0.000443848</ixy>
          <ixz>-0.00021115</ixz>
          <iyy>0.00700538</iyy>
          <iyz>0.000153481</iyz>
          <izz>0.00552755</izz>
        </inertia>
      </inertial>
      <collision name='left_lower_forearm_collision'>
        <pose>0 0 0 0 -0 0</pose>
        <geometry>
          <cylinder>
            <length>0.1</length>
            <radius>0.06</radius>
          </cylinder>
        </geometry>
      </collision>
      <visual name='left_lower_forearm_visual'>
        <pose>0 0 0 0 -0 0</pose>
        <geometry>
          <mesh>
            <scale>1 1 1</scale>
            <uri>model://baxter_description/meshes/lower_forearm/W1.DAE</uri>
          </mesh>
        </geometry>
      </visual>
    </link>
    <joint name='left_w2' type='revolute'>
      <pose relative_to='left_lower_forearm'>0.115975 0 0 1.5708 -0 1.5708</pose>
      <parent>left_lower_forearm</parent>
      <child>left_wrist</child>
      <axis>
        <xyz>0 0 1</xyz>
        <limit>
          <lower>-3.059</lower>
          <upper>3.059</upper>
          <effort>15</effort>
          <velocity>4</velocity>
        </limit>
        <dynamics>
          <damping>0.7</damping>
          <friction>0</friction>
          <spring_reference>0</spring_reference>
          <spring_stiffness>0</spring_stiffness>
        </dynamics>
      </axis>
      <physics>
        <ode>
          <implicit_spring_damper>1</implicit_spring_damper>
          <cfm_damping>1</cfm_damping>
          <limit>
            <cfm>0</cfm>
            <erp>0.2</erp>
          </limit>
        </ode>
      </physics>
    </joint>
    <link name='left_wrist'>
      <pose relative_to='left_w2'>0 0 0 0 -0 0</pose>
      <inertial>
        <pose>0.005152 0.000957 0.046743 0 -0 0</pose>
        <mass>0.54278</mass>
        <inertia>
          <ixx>0.00121873</ixx>
          <ixy>8.12598e-06</ixy>
          <ixz>-6.62108e-05</ixz>
          <iyy>0.00128054</iyy>
          <iyz>4.75609e-06</iyz>
          <izz>0.000555294</izz>
        </inertia>
      </inertial>
      <collision name='left_wrist_collision'>
        <pose>0 0 0 0 -0 0</pose>
        <geometry>
          <cylinder>
            <length>0.165</length>
            <radius>0.06</radius>
          </cylinder>
        </geometry>
      </collision>
      <collision name='left_wrist_fixed_joint_lump__left_hand_collision_1'>
        <pose>0 0 0.09035 0 -0 0</pose>
        <geometry>
          <cylinder>
            <length>0.0464</length>
            <radius>0.04</radius>
          </cylinder>
        </geometry>
      </collision>
      <visual name='left_wrist_visual'>
        <pose>0 0 0 0 -0 0</pose>
        <geometry>
          <mesh>
            <scale>1 1 1</scale>
            <uri>model://baxter_description/meshes/wrist/W2.DAE</uri>
          </mesh>
        </geometry>
      </visual>
      <visual name='left_wrist_fixed_joint_lump__left_gripper_base_visual_1'>
        <pose>0 0 0.09355 0 -0 0</pose>
        <geometry>
          <box>
            <size>0.025 0.075 0.035</size>
          </box>
        </geometry>
      </visual>
      <visual name='left_wrist_fixed_joint_lump__left_gripper_visual_2'>
        <pose>0 0 0.13855 0 -0 0</pose>
        <geometry>
          <box>
            <size>0.01 0.01 0.01</size>
          </box>
        </geometry>
      </visual>
      <visual name='left_wrist_fixed_joint_lump__left_hand_accelerometer_visual_3'>
        <pose>0.00198 0.000133 0.09895 0 -0 0</pose>
        <geometry>
          <box>
            <size>0.01 0.01 0.01</size>
          </box>
        </geometry>
      </visual>
      <visual name='left_wrist_fixed_joint_lump__left_hand_camera_visual_4'>
        <pose>0.03825 0.012 0.128905 0 0 -1.5708</pose>
        <geometry>
          <cylinder>
            <length>0.01</length>
            <radius>0.02</radius>
          </cylinder>
        </geometry>
      </visual>
      <visual name='left_wrist_fixed_joint_lump__left_hand_range_visual_5'>
        <pose>0.032 -0.020245 0.14235 -1.5708 -1.5708 0</pose>
        <geometry>
          <box>
            <size>0.005 0.02 0.005</size>
          </box>
        </geometry>
      </visual>
      <sensor name='left_hand_camera' type='camera'>
        <update_rate>30</update_rate>
        <camera name='left_hand_camera'>
          <pose>0 0 0 1.5708 -1.5708 0</pose>
          <horizontal_fov>1.39626</horizontal_fov>
          <image>
            <width>800</width>
            <height>800</height>
            <format>R8G8B8</format>
          </image>
          <clip>
            <near>0.02</near>
            <far>300</far>
          </clip>
          <noise>
            <type>gaussian</type>
            <mean>0</mean>
            <stddev>0.007</stddev>
          </noise>
        </camera>
        <plugin name='camera_controller' filename='libgazebo_ros_camera.so'>
          <alwaysOn>1</alwaysOn>
          <updateRate>0.0</updateRate>
          <cameraName>left_hand_camera</cameraName>
          <imageTopicName>image</imageTopicName>
          <cameraInfoTopicName>camera_info</cameraInfoTopicName>
          <frameName>left_hand_camera</frameName>
          <hackBaseline>0.07</hackBaseline>
          <distortionK1>0.0</distortionK1>
          <distortionK2>0.0</distortionK2>
          <distortionK3>0.0</distortionK3>
          <distortionT1>0.0</distortionT1>
          <distortionT2>0.0</distortionT2>
          <robotNamespace>/cameras</robotNamespace>
        </plugin>
        <pose>0.03825 0.012 0.128905 0 0 -1.5708</pose>
      </sensor>
      <sensor name='ir_left' type='ray'>
        <ray>
          <scan>
            <horizontal>
              <samples>1</samples>
              <resolution>1</resolution>
              <min_angle>-0.5</min_angle>
              <max_angle>0.5</max_angle>
            </horizontal>
          </scan>
          <range>
            <min>0.004</min>
            <max>0.4</max>
          </range>
        </ray>
        <plugin name='plugin_4' filename='libgazebo_ros_laser.so'>
          <gaussianNoise>0.005</gaussianNoise>
          <alwaysOn>1</alwaysOn>
          <updateRate>100</updateRate>
          <topicName>/sim/laserscan/left_hand_range/state</topicName>
          <frameName>left_hand_range</frameName>
        </plugin>
        <always_on>1</always_on>
        <update_rate>100</update_rate>
        <pose>0.032 -0.020245 0.14235 3.14159 -1.57079 1.57079</pose>
      </sensor>
    </link>
    <joint name='right_s0' type='revolute'>
      <pose relative_to='base'>0.064027 -0.259027 0.129626 0 0 -0.7854</pose>
      <parent>base</parent>
      <child>right_upper_shoulder</child>
      <axis>
        <xyz>0 0 1</xyz>
        <limit>
          <lower>-1.70168</lower>
          <upper>1.70168</upper>
          <effort>50</effort>
          <velocity>1.5</velocity>
        </limit>
        <dynamics>
          <damping>0.7</damping>
          <friction>0</friction>
          <spring_reference>0</spring_reference>
          <spring_stiffness>0</spring_stiffness>
        </dynamics>
      </axis>
      <physics>
        <ode>
          <implicit_spring_damper>1</implicit_spring_damper>
          <cfm_damping>1</cfm_damping>
          <limit>
            <cfm>0</cfm>
            <erp>0.2</erp>
          </limit>
        </ode>
      </physics>
    </joint>
    <link name='right_upper_shoulder'>
      <pose relative_to='right_s0'>0 0 0 0 -0 0</pose>
      <inertial>
        <pose>0.01783 0.00086 0.19127 0 -0 0</pose>
        <mass>5.70044</mass>
        <inertia>
          <ixx>0.047091</ixx>
          <ixy>0.000127876</ixy>
          <ixz>0.0061487</ixz>
          <iyy>0.0376698</iyy>
          <iyz>0.000780869</iyz>
          <izz>0.0359599</izz>
        </inertia>
      </inertial>
      <collision name='right_upper_shoulder_collision'>
        <pose>0 0 0.1361 0 -0 0</pose>
        <geometry>
          <cylinder>
            <length>0.2722</length>
            <radius>0.06</radius>
          </cylinder>
        </geometry>
      </collision>
      <visual name='right_upper_shoulder_visual'>
        <pose>0 0 0 0 -0 0</pose>
        <geometry>
          <mesh>
            <scale>1 1 1</scale>
            <uri>model://baxter_description/meshes/upper_shoulder/S0.DAE</uri>
          </mesh>
        </geometry>
      </visual>
    </link>
    <joint name='right_s1' type='revolute'>
      <pose relative_to='right_upper_shoulder'>0.069 0 0.27035 -1.5708 0 0</pose>
      <parent>right_upper_shoulder</parent>
      <child>right_lower_shoulder</child>
      <axis>
        <xyz>0 0 1</xyz>
        <limit>
          <lower>-2.147</lower>
          <upper>1.047</upper>
          <effort>100</effort>
          <velocity>1.5</velocity>
        </limit>
        <dynamics>
          <damping>0.7</damping>
          <friction>0</friction>
          <spring_reference>0</spring_reference>
          <spring_stiffness>0</spring_stiffness>
        </dynamics>
      </axis>
      <physics>
        <ode>
          <implicit_spring_damper>1</implicit_spring_damper>
          <cfm_damping>1</cfm_damping>
          <limit>
            <cfm>0</cfm>
            <erp>0.2</erp>
          </limit>
        </ode>
      </physics>
    </joint>
    <link name='right_lower_shoulder'>
      <pose relative_to='right_s1'>0 0 0 0 -0 0</pose>
      <inertial>
        <pose>0.068451 0.00269 -0.00529 0 -0 0</pose>
        <mass>3.22708</mass>
        <inertia>
          <ixx>0.0117521</ixx>
          <ixy>-0.000300954</ixy>
          <ixz>0.00207674</ixz>
          <iyy>0.0278861</iyy>
          <iyz>-0.000188219</iyz>
          <izz>0.0207877</izz>
        </inertia>
      </inertial>
      <collision name='right_lower_shoulder_collision'>
        <pose>0 0 0 0 -0 0</pose>
        <geometry>
          <cylinder>
            <length>0.12</length>
            <radius>0.06</radius>
          </cylinder>
        </geometry>
      </collision>
      <collision name='right_lower_shoulder_fixed_joint_lump__right_upper_elbow_visual_collision_1'>
        <pose>0.2435 -0 0 1.5708 -0 1.5708</pose>
        <geometry>
          <cylinder>
            <length>0.273</length>
            <radius>0.06</radius>
          </cylinder>
        </geometry>
      </collision>
      <visual name='right_lower_shoulder_visual'>
        <pose>0 0 0 0 -0 0</pose>
        <geometry>
          <mesh>
            <scale>1 1 1</scale>
            <uri>model://baxter_description/meshes/lower_shoulder/S1.DAE</uri>
          </mesh>
        </geometry>
      </visual>
    </link>
    <joint name='right_e0' type='revolute'>
      <pose relative_to='right_lower_shoulder'>0.102 0 0 1.5708 -0 1.5708</pose>
      <parent>right_lower_shoulder</parent>
      <child>right_upper_elbow</child>
      <axis>
        <xyz>0 0 1</xyz>
        <limit>
          <lower>-3.05418</lower>
          <upper>3.05418</upper>
          <effort>50</effort>
          <velocity>1.5</velocity>
        </limit>
        <dynamics>
          <damping>0.7</damping>
          <friction>0</friction>
          <spring_reference>0</spring_reference>
          <spring_stiffness>0</spring_stiffness>
        </dynamics>
      </axis>
      <physics>
        <ode>
          <implicit_spring_damper>1</implicit_spring_damper>
          <cfm_damping>1</cfm_damping>
          <limit>
            <cfm>0</cfm>
            <erp>0.2</erp>
          </limit>
        </ode>
      </physics>
    </joint>
    <link name='right_upper_elbow'>
      <pose relative_to='right_e0'>0 0 0 0 -0 0</pose>
      <inertial>
        <pose>-0.00276 0.00132 0.18086 0 -0 0</pose>
        <mass>4.31272</mass>
        <inertia>
          <ixx>0.0266173</ixx>
          <ixy>0.000292706</ixy>
          <ixz>0.0039219</ixz>
          <iyy>0.0284436</iyy>
          <iyz>0.00108389</iyz>
          <izz>0.0124801</izz>
        </inertia>
      </inertial>
      <collision name='right_upper_elbow_collision'>
        <pose>0 0 -0.0535 0 -0 0</pose>
        <geometry>
          <cylinder>
            <length>0.107</length>
            <radius>0.06</radius>
          </cylinder>
        </geometry>
      </collision>
      <visual name='right_upper_elbow_visual'>
        <pose>0 0 0 0 -0 0</pose>
        <geometry>
          <mesh>
            <scale>1 1 1</scale>
            <uri>model://baxter_description/meshes/upper_elbow/E0.DAE</uri>
          </mesh>
        </geometry>
      </visual>
    </link>
    <joint name='right_e1' type='revolute'>
      <pose relative_to='right_upper_elbow'>0.069 0 0.26242 -1.5708 -1.5708 0</pose>
      <parent>right_upper_elbow</parent>
      <child>right_lower_elbow</child>
      <axis>
        <xyz>0 0 1</xyz>
        <limit>
          <lower>-0.05</lower>
          <upper>2.618</upper>
          <effort>50</effort>
          <velocity>1.5</velocity>
        </limit>
        <dynamics>
          <damping>0.7</damping>
          <friction>0</friction>
          <spring_reference>0</spring_reference>
          <spring_stiffness>0</spring_stiffness>
        </dynamics>
      </axis>
      <physics>
        <ode>
          <implicit_spring_damper>1</implicit_spring_damper>
          <cfm_damping>1</cfm_damping>
          <limit>
            <cfm>0</cfm>
            <erp>0.2</erp>
          </limit>
        </ode>
      </physics>
    </joint>
    <link name='right_lower_elbow'>
      <pose relative_to='right_e1'>0 0 0 0 -0 0</pose>
      <inertial>
        <pose>0.026113 0.00159 -0.011169 0 -0 0</pose>
        <mass>2.07216</mass>
        <inertia>
          <ixx>0.00711585</ixx>
          <ixy>0.000360372</ixy>
          <ixz>0.00074588</ixz>
          <iyy>0.0131827</iyy>
          <iyz>-0.000196632</iyz>
          <izz>0.00926891</izz>
        </inertia>
      </inertial>
      <collision name='right_lower_elbow_collision'>
        <pose>0 0 0 0 -0 0</pose>
        <geometry>
          <cylinder>
            <length>0.1</length>
            <radius>0.06</radius>
          </cylinder>
        </geometry>
      </collision>
      <collision name='right_lower_elbow_fixed_joint_lump__right_upper_forearm_visual_collision_1'>
        <pose>0.224 -0 0 1.5708 -0 1.5708</pose>
        <geometry>
          <cylinder>
            <length>0.272</length>
            <radius>0.06</radius>
          </cylinder>
        </geometry>
      </collision>
      <visual name='right_lower_elbow_visual'>
        <pose>0 0 0 0 -0 0</pose>
        <geometry>
          <mesh>
            <scale>1 1 1</scale>
            <uri>model://baxter_description/meshes/lower_elbow/E1.DAE</uri>
          </mesh>
        </geometry>
      </visual>
    </link>
    <joint name='right_w0' type='revolute'>
      <pose relative_to='right_lower_elbow'>0.10359 0 0 1.5708 -0 1.5708</pose>
      <parent>right_lower_elbow</parent>
      <child>right_upper_forearm</child>
      <axis>
        <xyz>0 0 1</xyz>
        <limit>
          <lower>-3.059</lower>
          <upper>3.059</upper>
          <effort>15</effort>
          <velocity>4</velocity>
        </limit>
        <dynamics>
          <damping>0.7</damping>
          <friction>0</friction>
          <spring_reference>0</spring_reference>
          <spring_stiffness>0</spring_stiffness>
        </dynamics>
      </axis>
      <physics>
        <ode>
          <implicit_spring_damper>1</implicit_spring_damper>
          <cfm_damping>1</cfm_damping>
          <limit>
            <cfm>0</cfm>
            <erp>0.2</erp>
          </limit>
        </ode>
      </physics>
    </joint>
    <link name='right_upper_forearm'>
      <pose relative_to='right_w0'>0 0 0 0 -0 0</pose>
      <inertial>
        <pose>-0.001682 0.0046 0.139519 0 -0 0</pose>
        <mass>2.24675</mass>
        <inertia>
          <ixx>0.0166775</ixx>
          <ixy>0.000184012</ixy>
          <ixz>0.000186469</ixz>
          <iyy>0.0167549</iyy>
          <iyz>-0.000647332</iyz>
          <izz>0.00374662</izz>
        </inertia>
      </inertial>
      <collision name='right_upper_forearm_collision'>
        <pose>0 0 -0.044 0 -0 0</pose>
        <geometry>
          <cylinder>
            <length>0.088</length>
            <radius>0.06</radius>
          </cylinder>
        </geometry>
      </collision>
      <visual name='right_upper_forearm_visual'>
        <pose>0 0 0 0 -0 0</pose>
        <geometry>
          <mesh>
            <scale>1 1 1</scale>
            <uri>model://baxter_description/meshes/upper_forearm/W0.DAE</uri>
          </mesh>
        </geometry>
      </visual>
    </link>
    <joint name='right_w1' type='revolute'>
      <pose relative_to='right_upper_forearm'>0.01 0 0.2707 -1.5708 -1.5708 0</pose>
      <parent>right_upper_forearm</parent>
      <child>right_lower_forearm</child>
      <axis>
        <xyz>0 0 1</xyz>
        <limit>
          <lower>-1.5708</lower>
          <upper>2.094</upper>
          <effort>15</effort>
          <velocity>4</velocity>
        </limit>
        <dynamics>
          <damping>0.7</damping>
          <friction>0</friction>
          <spring_reference>0</spring_reference>
          <spring_stiffness>0</spring_stiffness>
        </dynamics>
      </axis>
      <physics>
        <ode>
          <implicit_spring_damper>1</implicit_spring_damper>
          <cfm_damping>1</cfm_damping>
          <limit>
            <cfm>0</cfm>
            <erp>0.2</erp>
          </limit>
        </ode>
      </physics>
    </joint>
    <link name='right_lower_forearm'>
      <pose relative_to='right_w1'>0 0 0 0 -0 0</pose>
      <inertial>
        <pose>0.06041 0.00697 0.006 0 -0 0</pose>
        <mass>1.60979</mass>
        <inertia>
          <ixx>0.00387607</ixx>
          <ixy>-0.000443848</ixy>
          <ixz>-0.00021115</ixz>
          <iyy>0.00700538</iyy>
          <iyz>0.000153481</iyz>
          <izz>0.00552755</izz>
        </inertia>
      </inertial>
      <collision name='right_lower_forearm_collision'>
        <pose>0 0 0 0 -0 0</pose>
        <geometry>
          <cylinder>
            <length>0.1</length>
            <radius>0.06</radius>
          </cylinder>
        </geometry>
      </collision>
      <visual name='right_lower_forearm_visual'>
        <pose>0 0 0 0 -0 0</pose>
        <geometry>
          <mesh>
            <scale>1 1 1</scale>
            <uri>model://baxter_description/meshes/lower_forearm/W1.DAE</uri>
          </mesh>
        </geometry>
      </visual>
    </link>
    <joint name='right_w2' type='revolute'>
      <pose relative_to='right_lower_forearm'>0.115975 0 0 1.5708 -0 1.5708</pose>
      <parent>right_lower_forearm</parent>
      <child>right_wrist</child>
      <axis>
        <xyz>0 0 1</xyz>
        <limit>
          <lower>-3.059</lower>
          <upper>3.059</upper>
          <effort>15</effort>
          <velocity>4</velocity>
        </limit>
        <dynamics>
          <damping>0.7</damping>
          <friction>0</friction>
          <spring_reference>0</spring_reference>
          <spring_stiffness>0</spring_stiffness>
        </dynamics>
      </axis>
      <physics>
        <ode>
          <implicit_spring_damper>1</implicit_spring_damper>
          <cfm_damping>1</cfm_damping>
          <limit>
            <cfm>0</cfm>
            <erp>0.2</erp>
          </limit>
        </ode>
      </physics>
    </joint>
    <link name='right_wrist'>
      <pose relative_to='right_w2'>0 0 0 0 -0 0</pose>
      <inertial>
        <pose>0.005152 0.000957 0.046743 0 -0 0</pose>
        <mass>0.54278</mass>
        <inertia>
          <ixx>0.00121873</ixx>
          <ixy>8.12598e-06</ixy>
          <ixz>-6.62108e-05</ixz>
          <iyy>0.00128054</iyy>
          <iyz>4.75609e-06</iyz>
          <izz>0.000555294</izz>
        </inertia>
      </inertial>
      <collision name='right_wrist_collision'>
        <pose>0 0 0 0 -0 0</pose>
        <geometry>
          <cylinder>
            <length>0.165</length>
            <radius>0.06</radius>
          </cylinder>
        </geometry>
      </collision>
      <collision name='right_wrist_fixed_joint_lump__right_hand_collision_1'>
        <pose>0 0 0.09035 0 -0 0</pose>
        <geometry>
          <cylinder>
            <length>0.0464</length>
            <radius>0.04</radius>
          </cylinder>
        </geometry>
      </collision>
      <visual name='right_wrist_visual'>
        <pose>0 0 0 0 -0 0</pose>
        <geometry>
          <mesh>
            <scale>1 1 1</scale>
            <uri>model://baxter_description/meshes/wrist/W2.DAE</uri>
          </mesh>
        </geometry>
      </visual>
      <visual name='right_wrist_fixed_joint_lump__right_gripper_base_visual_1'>
        <pose>0 0 0.09355 0 -0 0</pose>
        <geometry>
          <box>
            <size>0.025 0.075 0.035</size>
          </box>
        </geometry>
      </visual>
      <visual name='right_wrist_fixed_joint_lump__right_gripper_visual_2'>
        <pose>0 0 0.13855 0 -0 0</pose>
        <geometry>
          <box>
            <size>0.01 0.01 0.01</size>
          </box>
        </geometry>
      </visual>
      <visual name='right_wrist_fixed_joint_lump__right_hand_accelerometer_visual_3'>
        <pose>0.00198 0.000133 0.09895 0 -0 0</pose>
        <geometry>
          <box>
            <size>0.01 0.01 0.01</size>
          </box>
        </geometry>
      </visual>
      <visual name='right_wrist_fixed_joint_lump__right_hand_camera_visual_4'>
        <pose>0.03825 0.012 0.128905 0 0 -1.5708</pose>
        <geometry>
          <cylinder>
            <length>0.01</length>
            <radius>0.02</radius>
          </cylinder>
        </geometry>
      </visual>
      <visual name='right_wrist_fixed_joint_lump__right_hand_range_visual_5'>
        <pose>0.032 -0.020245 0.14235 -1.5708 -1.5708 0</pose>
        <geometry>
          <box>
            <size>0.005 0.02 0.005</size>
          </box>
        </geometry>
      </visual>
      <sensor name='right_hand_camera' type='camera'>
        <update_rate>30</update_rate>
        <camera name='right_hand_camera'>
          <pose>0 0 0 1.5708 -1.5708 0</pose>
          <horizontal_fov>1.39626</horizontal_fov>
          <image>
            <width>800</width>
            <height>800</height>
            <format>R8G8B8</format>
          </image>
          <clip>
            <near>0.02</near>
            <far>300</far>
          </clip>
          <noise>
            <type>gaussian</type>
            <mean>0</mean>
            <stddev>0.007</stddev>
          </noise>
        </camera>
        <plugin name='camera_controller' filename='libgazebo_ros_camera.so'>
          <alwaysOn>1</alwaysOn>
          <updateRate>0.0</updateRate>
          <cameraName>right_hand_camera</cameraName>
          <imageTopicName>image</imageTopicName>
          <cameraInfoTopicName>camera_info</cameraInfoTopicName>
          <frameName>right_hand_camera</frameName>
          <hackBaseline>0.07</hackBaseline>
          <distortionK1>0.0</distortionK1>
          <distortionK2>0.0</distortionK2>
          <distortionK3>0.0</distortionK3>
          <distortionT1>0.0</distortionT1>
          <distortionT2>0.0</distortionT2>
          <robotNamespace>/cameras</robotNamespace>
        </plugin>
        <pose>0.03825 0.012 0.128905 0 0 -1.5708</pose>
      </sensor>
      <sensor name='ir_right' type='ray'>
        <ray>
          <scan>
            <horizontal>
              <samples>1</samples>
              <resolution>1</resolution>
              <min_angle>-0.5</min_angle>
              <max_angle>0.5</max_angle>
            </horizontal>
          </scan>
          <range>
            <min>0.004</min>
            <max>0.4</max>
          </range>
        </ray>
        <plugin name='plugin_3' filename='libgazebo_ros_laser.so'>
          <gaussianNoise>0.005</gaussianNoise>
          <alwaysOn>1</alwaysOn>
          <updateRate>100</updateRate>
          <topicName>/sim/laserscan/right_hand_range/state</topicName>
          <frameName>right_hand_range</frameName>
        </plugin>
        <always_on>1</always_on>
        <update_rate>100</update_rate>
        <pose>0.032 -0.020245 0.14235 3.14159 -1.57079 1.57079</pose>
      </sensor>
    </link>
    <static>0</static>
    <plugin name='baxter_ros_control' filename='libbaxter_gazebo_ros_control.so'>
      <robotNamespace>/robot</robotNamespace>
    </plugin>
  </model>
</sdf>
