<?xml version="1.0" ?>
<sdf version="1.7">
	<model name="Fridge">
		<link name="base">
			<visual name="fridge_visual_1">
				<geometry>
					<mesh>
						<scale>1 1 1</scale>
						<uri>meshes/Fridge_W70_D60_H190_Cube_056.fbx</uri>
					</mesh>
				</geometry>
			</visual>
		</link>

		<joint name="fridge_door_1_joint" type="revolute">
			<pose>0.3 0.35 0.05 0 0 -1.5708</pose>
			<axis>
				<xyz>0 0 1</xyz>
			</axis>
			<parent>base</parent>
			<child>fridge_door_1</child>
			<limit>
				<lower>0</lower>
				<upper>0.7</upper>
				<velocity>0</velocity>
				<effort>0</effort>
			</limit>
		</joint>
		<link name="fridge_door_1">
			<visual name="fridge_door_1_visual">
				<geometry>
					<mesh>
						<scale>1 1 1</scale>
						<uri>meshes/Fridge_W70_D60_H190_Cube_054.fbx</uri>
					</mesh>
				</geometry>
			</visual>
		</link>

		<joint name="fridge_door_1_handle_joint" type="fixed">
			<pose>0.65 0.03 0.7 0 1.5708 1.5708</pose>
			<parent>fridge_door_1</parent>
			<child>fridge_door_1_handle</child>
		</joint>
		<link name="fridge_door_1_handle">
			<visual name="door_1_handle_visual">
				<geometry>
					<mesh>
						<scale>1 1 1</scale>
						<uri>meshes/Fridge_W70_D60_H190_Cylinder_007.fbx</uri>
					</mesh>
				</geometry>
			</visual>
		</link>

		<joint name="fridge_door_2_joint" type="revolute">
			<pose>0.3 0.35 0.86 0 0 -1.5708</pose>
			<axis>
				<xyz>0 0 1</xyz>
			</axis>
			<parent>base</parent>
			<child>fridge_door_2</child>
			<limit>
				<lower>0</lower>
				<upper>0.7</upper>
				<velocity>0</velocity>
				<effort>0</effort>
			</limit>
		</joint>
		<link name="fridge_door_2">
			<visual name="fridge_door_2_visual">
				<geometry>
					<mesh>
						<scale>1 1 1</scale>
						<uri>meshes/Fridge_W70_D60_H190_Cube_055.fbx</uri>
					</mesh>
				</geometry>
			</visual>
		</link>

		<joint name="fridge_door_2_handle_joint" type="fixed">
			<pose>0.65 0.03 0.86 0 -1.5708 -1.5708</pose>
			<parent>fridge_door_2</parent>
			<child>fridge_door_2_handle</child>
		</joint>
		<link name="fridge_door_2_handle">
			<visual name="door_2_handle_visual">
				<geometry>
					<mesh>
						<scale>1 1 1</scale>
						<uri>meshes/Fridge_W70_D60_H190_Cylinder_008.fbx</uri>
					</mesh>
				</geometry>
			</visual>
		</link>
	</model>
</sdf>